AttributeError: This app has encountered an error. The original error message is redacted to prevent data leaks. Full error details have been recorded in the logs (if you're on Streamlit Cloud, click on 'Manage app' in the lower right of your app).
Traceback:
File "/mount/src/medbot-streamlit/main.py", line 54, in <module>
    main()
    ~~~~^^
File "/mount/src/medbot-streamlit/main.py", line 37, in main
    create_dynamic_sidebar()
    ~~~~~~~~~~~~~~~~~~~~~~^^
File "/mount/src/medbot-streamlit/ui/sidebar.py", line 179, in create_dynamic_sidebar
    display_appointment_status()
    ~~~~~~~~~~~~~~~~~~~~~~~~~~^^
File "/mount/src/medbot-streamlit/ui/sidebar.py", line 40, in display_appointment_status
    appointment_status = get_appointment_integration_status()
File "/mount/src/medbot-streamlit/appointment_system/integration.py", line 178, in get_appointment_integration_status
    return appointment_integration.get_appointment_status()
           ~~~~~~~~~~~~~~~~~~~~~~~~~~~~~~~~~~~~~~~~~~~~~~^^
File "/mount/src/medbot-streamlit/appointment_system/integration.py", line 129, in get_appointment_status
    "reference_number": appointment_data.get("appointment", {}).get("reference_number") if appointment_data.get("appointment") else None,
                        ^^^^^^^^^^^^^^^^^^^^^^^^^^^^^^^^^^^^^^^^^^^



